<?xml version="1.0"?>
<robot name="my_robot" xmlns:xacro="http://www.ros.org/wiki/xacro">

  <!-- 参数定义 -->
  <xacro:property name="base_width" value="0.4"/>
  <xacro:property name="base_length" value="1.0"/>
  <xacro:property name="wheel_radius" value="0.1"/>
  <xacro:property name="wheel_width" value="0.05"/>

  <!-- 颜色宏 -->
  <material name="blue"> <color rgba="0 0 0.8 1"/> </material>
  <material name="black"> <color rgba="0 0 0 1"/> </material>

  <!-- 惯性矩阵宏 (Gazebo仿真必备，否则模型会乱飞) -->
  <xacro:macro name="default_inertial" params="mass">
    <inertial>
      <mass value="${mass}"/>
      <inertia ixx="0.01" ixy="0.0" ixz="0.0" iyy="0.01" iyz="0.0" izz="0.01"/>
    </inertial>
  </xacro:macro>

  <link name="base_footprint"/>

  <joint name="base_joint" type="fixed">
    <parent link="base_footprint"/>
    <child link="base_link"/>
    <origin xyz="0 0 0.1" rpy="0 0 0"/> 
  </joint>

  <!-- 1. 底盘 -->
  <link name="base_link">
    <visual>
      <geometry> <box size="${base_length} ${base_width} 0.1"/> </geometry>
      <material name="blue"/>
    </visual>
    <collision>
      <geometry> <box size="${base_length} ${base_width} 0.1"/> </geometry>
    </collision>
    <xacro:default_inertial mass="5.0"/>
  </link>

  <!-- 2. 轮子宏 -->
  <xacro:macro name="wheel" params="prefix reflect">
    <link name="${prefix}_wheel">
      <visual>
        <geometry> <cylinder radius="${wheel_radius}" length="${wheel_width}"/> </geometry>
        <material name="black"/>
      </visual>
      <collision>
        <geometry> <cylinder radius="${wheel_radius}" length="${wheel_width}"/> </geometry>
      </collision>
      <xacro:default_inertial mass="1.0"/>
    </link>

    <joint name="${prefix}_wheel_joint" type="continuous">
      <parent link="base_link"/>
      <child link="${prefix}_wheel"/>
      <origin xyz="-0.2 ${reflect * (base_width/2 + wheel_width/2)} -0.05" rpy="-1.57 0 0"/>
      <axis xyz="0 0 1"/>
    </joint>
  </xacro:macro>

  <!-- 调用轮子宏 -->
  <xacro:wheel prefix="left" reflect="1"/>
  <xacro:wheel prefix="right" reflect="-1"/>

    <!-- 添加支撑脚 (万向轮) -->
  <link name="caster_wheel">
    <visual>
      <geometry> <sphere radius="0.05"/> </geometry>
      <material name="black"/>
    </visual>
    <collision>
      <geometry> <sphere radius="0.05"/> </geometry>
    </collision>
    <xacro:default_inertial mass="0.5"/>
  </link>

  <!-- 支撑脚关节 (固定连接) -->
  <joint name="caster_joint" type="fixed">
    <parent link="base_link"/>
    <child link="caster_wheel"/>
    <origin xyz="0.4 0 -0.1" rpy="0 0 0"/>
  </joint>

  <!-- 给万向轮设置摩擦力 (Gazebo 专用) -->
  <gazebo reference="caster_wheel">
    <mu1>0.0</mu1>
    <mu2>0.0</mu2>
  </gazebo>

    <!-- 激光雷达 Link -->
  <link name="laser_link">
    <visual>
      <geometry> <cylinder radius="0.03" length="0.05"/> </geometry>
      <material name="black"/>
    </visual>
    <collision>
      <geometry> <cylinder radius="0.03" length="0.05"/> </geometry>
    </collision>
    <xacro:default_inertial mass="0.1"/>
  </link>

  <!-- 激光雷达 Joint -->
  <joint name="laser_joint" type="fixed">
    <parent link="base_link"/>
    <child link="laser_link"/>
    <!-- 放在底盘上方 (base_z + 0.05/2) -->
    <origin xyz="0 0 0.075" rpy="0 0 0"/> 
  </joint>

  <!-- 3. Gazebo 差速驱动插件 -->
  <gazebo>
    <plugin name="differential_drive_controller" filename="libgazebo_ros_diff_drive.so">
      <legacyMode>false</legacyMode>
      <rosDebugLevel>na</rosDebugLevel> 
      <alwaysOn>true</alwaysOn>
      <updateRate>20</updateRate>
      <leftJoint>left_wheel_joint</leftJoint>
      <rightJoint>right_wheel_joint</rightJoint>
      <wheelSeparation>${base_width + wheel_width}</wheelSeparation>
      <wheelDiameter>${2 * wheel_radius}</wheelDiameter>
      <torque>20</torque>
      <commandTopic>cmd_vel</commandTopic>
      <odometryTopic>odom</odometryTopic>
      <odometryFrame>odom</odometryFrame>
      <robotBaseFrame>base_link</robotBaseFrame>
      <!-- 补充这些参数 -->
      <publishWheelTF>true</publishWheelTF>
      <publishOdomTF>true</publishOdomTF>
      <publishWheelJointState>true</publishWheelJointState>
      <wheelAcceleration>1.0</wheelAcceleration>
      <wheelTorque>20</wheelTorque>
      <odometrySource>world</odometrySource>
      <publishTf>1</publishTf>
    </plugin>
  </gazebo>

    <gazebo reference="laser_link">
        <sensor type="ray" name="head_hokuyo_sensor">
        <pose>0 0 0 0 0 0</pose>
        <visualize>true</visualize> <!-- 设置为 true，你就能在 Gazebo 里看到扫描线 -->
        <update_rate>40</update_rate>
        <ray>
            <scan>
            <horizontal>
                <samples>720</samples>
                <resolution>1</resolution>
                <min_angle>-1.570796</min_angle>
                <max_angle>1.570796</max_angle>
            </horizontal>
            </scan>
            <range>
            <min>0.10</min>
            <max>30.0</max>
            <resolution>0.01</resolution>
            </range>
        </ray>
        <plugin name="gazebo_ros_head_hokuyo_controller" filename="libgazebo_ros_laser.so">
            <topicName>/scan</topicName>
            <frameName>laser_link</frameName>
        </plugin>
        </sensor>
    </gazebo>

</robot>