<?xml version="1.0"?>
<robot name="simple_car" xmlns:xacro="http://www.ros.org/wiki/xacro">

  <material name="blue"><color rgba="0 0 0.8 1"/></material>
  <material name="black"><color rgba="0 0 0 1"/></material>

  <link name="base_link">
    <visual>
      <geometry><box size="0.4 0.2 0.1"/></geometry>
      <material name="blue"/>
    </visual>
    <collision>
      <geometry><box size="0.4 0.2 0.1"/></geometry>
    </collision>
    <inertial>
      <mass value="10"/>
      <inertia ixx="0.1" ixy="0" ixz="0" iyy="0.1" iyz="0" izz="0.1"/>
    </inertial>
  </link>

  <xacro:macro name="wheel" params="prefix reflect">
    <link name="${prefix}_wheel">
      <visual>
        <geometry><cylinder radius="0.05" length="0.02"/></geometry>
        <material name="black"/>
      </visual>
      <collision>
        <geometry><cylinder radius="0.05" length="0.02"/></geometry>
      </collision>
      <inertial>
        <mass value="1"/>
        <inertia ixx="0.01" ixy="0" ixz="0" iyy="0.01" iyz="0" izz="0.01"/>
      </inertial>
    </link>

    <joint name="${prefix}_wheel_joint" type="continuous">
      <parent link="base_link"/>
      <child link="${prefix}_wheel"/>
      <origin xyz="-0.1 ${reflect*0.12} -0.05" rpy="1.5707 0 0"/>
      <axis xyz="0 0 1"/>
    </joint>
  </xacro:macro>

  <xacro:wheel prefix="left" reflect="1"/>
  <xacro:wheel prefix="right" reflect="-1"/>

  <gazebo>
    <plugin name="differential_drive_controller" filename="libgazebo_ros_diff_drive.so">
      <rosDebugLevel>na</rosDebugLevel>
      <publishWheelTF>true</publishWheelTF>
      <robotNamespace>/</robotNamespace>
      <publishTf>1</publishTf>
      <publishWheelJointState>true</publishWheelJointState>
      <alwaysOn>true</alwaysOn>
      <updateRate>100.0</updateRate>
      <leftJoint>left_wheel_joint</leftJoint>
      <rightJoint>right_wheel_joint</rightJoint>
      <wheelSeparation>0.24</wheelSeparation>
      <wheelDiameter>0.1</wheelDiameter>
      <broadcastTF>1</broadcastTF>
      <wheelTorque>30</wheelTorque>
      <wheelAcceleration>1.8</wheelAcceleration>
      <commandTopic>cmd_vel</commandTopic>
      <odometryTopic>odom</odometryTopic>
      <odometryFrame>odom</odometryFrame>
      <robotBaseFrame>base_link</robotBaseFrame>
    </plugin>
  </gazebo>
</robot>
